<?xml version="1.0" encoding="utf-8"?>
<!-- This URDF was automatically created by SolidWorks to URDF Exporter! Originally created by Stephen Brawner (brawner@gmail.com) 
     Commit Version: 1.6.0-1-g15f4949  Build Version: 1.6.7594.29634
     For more information, please see http://wiki.ros.org/sw_urdf_exporter -->
<robot
  name="ip50_description">
  <link name="base_footprint">
  <link
    name="base_link">
    <inertial>
      <origin
        xyz="-0.00359081430135898 0.000612976584650871 0.115984201634212"
        rpy="0 0 0" />
      <mass
        value="5.09951409660043" />
      <inertia
        ixx="0.0687034546024341"
        ixy="4.44025688413578E-05"
        ixz="2.73618002973734E-05"
        iyy="0.0589347206836431"
        iyz="-1.1771465165278E-06"
        izz="0.118421661532089" />
    </inertial>
    <visual>
      <origin
        xyz="0 0 0"
        rpy="0 0 0" />
      <geometry>
        <mesh
          filename="package://ip50_description/meshes/base_link.STL" />
      </geometry>
      <material
        name="">
        <color
          rgba="0.752941176470588 0.752941176470588 0.752941176470588 1" />
      </material>
    </visual>
    <collision>
      <origin
        xyz="0 0 0"
        rpy="0 0 0" />
      <geometry>
        <mesh
          filename="package://ip50_description/meshes/base_link.STL" />
      </geometry>
    </collision>
  </link>
  <link
    name="l_wheel">
    <inertial>
      <origin
        xyz="-6.39147915030835E-05 -0.0905853223282888 7.52455301382352E-05"
        rpy="0 0 0" />
      <mass
        value="1.03119456963437" />
      <inertia
        ixx="0.00252579004887422"
        ixy="-6.96931534101966E-09"
        ixz="-3.76565286367825E-08"
        iyy="0.0011913930548909"
        iyz="8.20258306877417E-09"
        izz="0.00252580445292938" />
    </inertial>
    <visual>
      <origin
        xyz="0 0 0"
        rpy="0 0 0" />
      <geometry>
        <mesh
          filename="package://ip50_description/meshes/l_wheel.STL" />
      </geometry>
      <material
        name="">
        <color
          rgba="1 1 0 1" />
      </material>
    </visual>
    <collision>
      <origin
        xyz="0 0 0"
        rpy="0 0 0" />
      <geometry>
        <mesh
          filename="package://ip50_description/meshes/l_wheel.STL" />
      </geometry>
    </collision>
  </link>
  <joint
    name="base_footprint_fixed"
    type="fixed">
    <origin
      xyz="0 0 0.035"
      rpy="0 0 0" />
    <parent
      link="base_footprint" />
    <child
      link="base_link" />
  </joint>
  <joint
    name="l_wheel"
    type="continuous">
    <origin
      xyz="0.153568841929354 0.233 0.0649189536113456"
      rpy="0 0 0" />
    <parent
      link="base_link" />
    <child
      link="l_wheel" />
    <axis
      xyz="0 1 0" />
  </joint>
  <link
    name="r_wheel">
    <inertial>
      <origin
        xyz="8.44608240664069E-05 0.0905853223282886 -5.1121028711615E-05"
        rpy="0 0 0" />
      <mass
        value="1.03119456963437" />
      <inertia
        ixx="0.00252581592441382"
        ixy="-9.20745404366867E-09"
        ixz="-3.34840753113052E-08"
        iyy="0.00119139305489091"
        iyz="5.57463141556241E-09"
        izz="0.0025257785773898" />
    </inertial>
    <visual>
      <origin
        xyz="0 0 0"
        rpy="0 0 0" />
      <geometry>
        <mesh
          filename="package://ip50_description/meshes/r_wheel.STL" />
      </geometry>
      <material
        name="">
        <color
          rgba="1 1 0 1" />
      </material>
    </visual>
    <collision>
      <origin
        xyz="0 0 0"
        rpy="0 0 0" />
      <geometry>
        <mesh
          filename="package://ip50_description/meshes/r_wheel.STL" />
      </geometry>
    </collision>
  </link>
  <joint
    name="r_wheel"
    type="continuous">
    <origin
      xyz="0.153409027921221 -0.233 0.0650550618673174"
      rpy="0 0 0" />
    <parent
      link="base_link" />
    <child
      link="r_wheel" />
    <axis
      xyz="0 1 0" />
  </joint>
  <link
    name="front_lidar">
    <inertial>
      <origin
        xyz="-0.00621392548059696 0.000292037209406404 0.00329944121120278"
        rpy="0 0 0" />
      <mass
        value="0.0538364492864323" />
      <inertia
        ixx="7.61704419008689E-05"
        ixy="-9.09597166103703E-11"
        ixz="-4.32080088300476E-07"
        iyy="5.6676075965285E-05"
        iyz="2.64398670277882E-11"
        izz="3.97053253042906E-05" />
    </inertial>
    <visual>
      <origin
        xyz="0 0 0"
        rpy="0 0 0" />
      <geometry>
        <mesh
          filename="package://ip50_description/meshes/front_lidar.STL" />
      </geometry>
      <material
        name="">
        <color
          rgba="0.250980392156863 0.250980392156863 0.250980392156863 1" />
      </material>
    </visual>
    <collision>
      <origin
        xyz="0 0 0"
        rpy="0 0 0" />
      <geometry>
        <mesh
          filename="package://ip50_description/meshes/front_lidar.STL" />
      </geometry>
    </collision>
  </link>
  <joint
    name="front_lidar"
    type="continuous">
    <origin
      xyz="0.249660535015402 -0.000735955619811546 0.12780117295488"
      rpy="0 0 80" />
    <parent
      link="base_link" />
    <child
      link="front_lidar" />
    <axis
      xyz="0 0 1" />
  </joint>
  <link
    name="back_lidar">
    <inertial>
      <origin
        xyz="0.00621392548059707 -0.000292037209406737 0.00329944121120224"
        rpy="0 0 0" />
      <mass
        value="0.0538364492864316" />
      <inertia
        ixx="7.61704419008675E-05"
        ixy="-9.09597165316907E-11"
        ixz="4.32080088300656E-07"
        iyy="5.66760759652836E-05"
        iyz="-2.64398665847196E-11"
        izz="3.97053253042901E-05" />
    </inertial>
    <visual>
      <origin
        xyz="0 0 0"
        rpy="0 0 0" />
      <geometry>
        <mesh
          filename="package://ip50_description/meshes/back_lidar.STL" />
      </geometry>
      <material
        name="">
        <color
          rgba="0.250980392156863 0.250980392156863 0.250980392156863 1" />
      </material>
    </visual>
    <collision>
      <origin
        xyz="0 0 0"
        rpy="0 0 0" />
      <geometry>
        <mesh
          filename="package://ip50_description/meshes/back_lidar.STL" />
      </geometry>
    </collision>
  </link>
  <joint
    name="back_lidar"
    type="continuous">
    <origin
      xyz="-0.249660535015403 0.000735955619811768 0.12775117295488"
      rpy="0 0 0" />
    <parent
      link="base_link" />
    <child
      link="back_lidar" />
    <axis
      xyz="0 0 1" />
  </joint>
</robot>